Workbook

Sheet TomTat_SuaLoi
A1: FineZip — bảng số liệu đã sửa & danh sách lỗi
A2: Mọi con số gốc lấy từ FineZipExperiment.xlsx và 5 notebook đã tải lên; công thức tính lại nằm ở các sheet GD*.
A4: Có bắt buộc chạy lại không?
A5: KHÔNG để sửa bảng: các lỗi 1–6 chỉ là tính toán/trình bày lại từ số đã có. Cần bổ sung (không bắt buộc cho phần sửa): đo kích thước adapter (không cần GPU), thời gian giải nén + GPU peak của FineZip (vài chục phút, đề bài có yêu cầu). Chi tiết ở sheet CanChayLai.
A7: # | B7: Vấn đề trong bản gốc | C7: Bản gốc ghi | D7: Sau khi sửa | E7: Chạy lại?
A8: 1 | B8: Cột 'Compressed size ≈ B' của LLMZip-lite sai ở ctx 32–256 (chia bit cho 10 thay vì 8) | C8: 149,487 / 134,948 / 125,485 / 116,416 B | D8: ≈ 186,860 / 168,685 / 156,856 / 145,521 B (GD3_FixedContext, mục B). Cột ratio trước đây đã đúng. | E8: Không
A9: 2 | B9: Hai quy ước 'ratio' trộn lẫn (gốc/nén và nén/gốc) | C9: 0.18686 cạnh 5.352× | D9: Chuẩn hoá: Ratio = gốc/nén (×); Compressed % = nén/gốc (cùng quy ước paper). | E9: Không
A10: 3 | B10: Bảng LoRA so sánh sai cặp (khác pipeline) | C10: GPT-2 128: 4.154× vs LoRA 6.657× | D10: Cùng AC: 6.375× → 6.657× (ctx128), 7.028× → 7.363× (ctx512): giảm kích thước 4.2% / 4.6% (GD35_LoRA, mục 1). | E10: Không
A11: 4 | B11: Chưa tính kích thước adapter vào file nén | C11: 3,253,104 bytes (≈3.10 MiB) | D11: Adapter 811.008 tham số ≈ 1.6 MB (fp16) – 3.2 MB (fp32) ≫ file nén 136 KB → ở 1 MB LoRA không có lợi ròng; điểm hoà vốn ≳ 250 MB (GD35_LoRA, mục 2). | E11: Chỉ cần đo adapter thật (ls) done
A12: 5 | B12: Thời gian so sánh khác batch (LLMZip-lite & FineZip ctx32 batch 1; FineZip GĐ3 batch 64) | C12: FineZip ctx32: 2740 s (GĐ2) vs 61.6 s (GĐ3) | D12: Thêm cột Batch; hệ số 45× chỉ do batch (GD2_Baseline!B19). Không kết luận 'FineZip nhanh hơn LLMZip-lite N lần'. | E12: Không (tuỳ chọn: cùng batch)
A13: 6 | B13: Hai lần đo thời gian enc FineZip khác nhau | C13: 61.6 / 67.2 / 83.0 / 114.3 / 178.8 vs 60.8 / 69.1 / 88.8 / 124.8 / 199.0 | D13: Giữ cả hai, dùng số từ file .txt, hiển thị độ lệch 3–11%. | E13: Tuỳ chọn
A14: 7 | B14: Mô tả pipeline sai ('FineZip của nhóm = context cố định + arithmetic coding') | C14: Sheet 'Đánh giá từng giai đoạn' | D14: eval_clean.py (FineZip) = rank + bzip2, chunk, batch. eval_ac.py ('LLMZip-lite') = AC + cửa sổ trượt. 'Context' hai bên khác nghĩa. | E14: Không
A15: 8 | B15: 'Training time/memory của LoRA chưa có' | C15: ⚠ chưa có | D15: Đã có trong notebook: 48.6 s, peak 2,749 MiB allocated / 3,024 MiB reserved (GD35_LoRA, mục 4). | E15: Không
A16: 9 | B16: Thiếu thời gian giải nén & GPU peak theo từng ctx (FineZip) | C16: Để trống / '...' | D16: Đánh dấu vàng 'CHƯA ĐO'. LLMZip-lite: dec ctx 32 đã đo, còn lại ghi ước tính ≈ enc. | E16: Nên (FineZip)
A17: 10 | B17: Hai số GPU memory mâu thuẫn | C17: 991 vs 1962 MiB | D17: Khác phạm vi đo (file 1 MB lúc nén vs test 315 B ở GĐ1); ghi chú, chưa kết luận. | E17: Nên đo lại cùng điều kiện

Sheet GD2_Baseline
A1: Giai đoạn 2 — Baseline trên 1 MB enwik8 (đã sửa)
A2: Chữ xanh = số lấy từ notebook/Excel cũ (input) · đen = công thức · xanh lá = liên kết sheet khác · vàng đỏ = chưa đo
A3: Original (bytes) | B3: 1000000
A4: Ký tự (chars, UTF-8 giải mã) | B4: 995768
A5: Token GPT-2 | B5: 286273
A7: Method | B7: Model | C7: Pipeline | D7: Context | E7: Batch | F7: AC bits (nếu có) | G7: Compressed (B) | H7: Ratio (gốc/nén) | I7: Compressed % (nén/gốc) | J7: Bits/char | K7: Enc (s) | L7: Dec (s) | M7: GPU peak (MiB) | N7: Lossless | O7: Tiết kiệm so với bzip2 | P7: Ghi chú
A8: gzip | B8: - | C8: DEFLATE | D8: - | E8: - | G8: 355808 | H8: =$B$3/G8 -> 2.8105045 | I8: =G8/$B$3 -> 0.355808 | J8: =G8*8/$B$4 -> 2.8585614 | K8: 0.0696 | L8: 0.0064 | M8: - | N8: ✓ | O8: =1-G8/$G$9 -> -0.26476683 | P8: GĐ2
A9: bzip2 | B9: - | C9: BWT | D9: - | E9: - | G9: 281323 | H9: =$B$3/G9 -> 3.5546329 | I9: =G9/$B$3 -> 0.281323 | J9: =G9*8/$B$4 -> 2.260149 | K9: 0.0951 | L9: 0.0408 | M9: - | N9: ✓ | O9: =1-G9/$G$9 -> 0 | P9: GĐ2
A10: LLMZip-lite | B10: GPT-2 | C10: AC + cửa sổ trượt (eval_ac.py) | D10: 32 | E10: 1 | F10: 1494873 | G10: =ROUNDUP(F10/8,0) -> 186860 | H10: =$B$3/G10 -> 5.3516001 | I10: =G10/$B$3 -> 0.18686 | J10: =G10*8/$B$4 -> 1.5012332 | K10: 2905.93 | L10: 2851.32 | M10: 995.75 | N10: ✓ | O10: =1-G10/$G$9 -> 0.33578129 | P10: Lần chạy GĐ3 đo lại enc = 2938.72 s. Bytes = ROUNDUP(bits/8).
A11: FineZip | B11: GPT-2 | C11: rank + bzip2, chunk (eval_clean.py) | D11: 32 | E11: 1 | G11: 293093 | H11: =$B$3/G11 -> 3.4118863 | I11: =G11/$B$3 -> 0.293093 | J11: =G11*8/$B$4 -> 2.3547091 | K11: 2740.09 | L11: 2761.86 | M11: 993.43 | N11: ✓ | O11: =1-G11/$G$9 -> -0.04183803 | P11: batch 1
A12: FineZip | B12: GPT-2 | C12: rank + bzip2, chunk (eval_clean.py) | D12: 32 | E12: 64 | G12: 293027 | H12: =$B$3/G12 -> 3.4126548 | I12: =G12/$B$3 -> 0.293027 | J12: =G12*8/$B$4 -> 2.3541789 | K12: 61.62886 | L12: CHƯA ĐO | M12: CHƯA ĐO | N12: ✓ | O12: =1-G12/$G$9 -> -0.041603424 | P12: batch 64 (số của GĐ3). Enc lấy từ dòng cuối file .txt.
A15: Hệ số suy ra từ bảng trên
A16: LLMZip-lite so với gzip (×) | B16: =H10/H8 -> 1.9041421
A17: LLMZip-lite so với bzip2 (×) | B17: =H10/H9 -> 1.5055282
A18: FineZip (bs=1) so với bzip2 (×) | B18: =H11/H9 -> 0.9598421
A19: Tăng tốc do batch: FineZip ctx32, bs 1 → bs 64 (×) | B19: =K11/K12 -> 44.46115
A20: Chênh kích thước FineZip bs1 − bs64 (B) | B20: =G11-G12 -> 66
A22: ⚠ Thời gian giữa các dòng KHÔNG so được thẳng: LLMZip-lite & FineZip(bs=1) chạy tuần tự (batch 1); FineZip(bs=64) chạy song song. Phần lớn chênh lệch tốc độ đến từ batch (ô B19), không phải từ thuật toán.
A23: ⚠ 'Context 32' ở hai pipeline khác nghĩa: LLMZip-lite = mọi token thấy 32 token trước (cửa sổ trượt); FineZip = chunk dài 32, token thứ i chỉ thấy i−1 token trong chunk.
A24: ⚠ GPU peak: 993–996 MiB (GĐ2) khác 1962 MiB (GĐ1, file test 315 B). Hai lần đo khác phạm vi → chưa kết luận; cần reset_peak_memory_stats() ngay trước mỗi lần nén.

Sheet GD3_FixedContext
A1: Giai đoạn 3 — Fixed Context 32…512 (đã sửa)
A2: Cùng 1 MB enwik8, GPT-2, Kaggle T4
A3: Original (B) | B3: =GD2_Baseline!B3 -> 1000000
A4: Chars | B4: =GD2_Baseline!B4 -> 995768
A6: A. FineZip (rank + bzip2, chunk, batch 64)
A7: Context (độ dài chunk) | B7: Compressed (B) | C7: Ratio (gốc/nén) | D7: Compressed % | E7: Δ ratio so với ctx 32 | F7: Enc (s) — từ file .txt | G7: Thời gian × so với ctx 32 | H7: Enc (s) — bảng thô Excel cũ | I7: Lệch giữa 2 lần đo | J7: Dec (s) | K7: GPU peak (MiB) | L7: Bit tiết kiệm / giây thêm (so mức trước) | M7: Lossless
A8: 32 | B8: 293027 | C8: =$B$3/B8 -> 3.4126548 | D8: =B8/$B$3 -> 0.293027 | E8: =C8/$C$8-1 -> 0 | F8: 61.62886 | G8: =F8/$F$8 -> 1 | H8: 60.808464 | I8: =H8/F8-1 -> -0.01331188 | J8: CHƯA ĐO | K8: CHƯA ĐO | L8: - | M8: ✓
A9: 64 | B9: 264110 | C9: =$B$3/B9 -> 3.7863012 | D9: =B9/$B$3 -> 0.26411 | E9: =C9/$C$8-1 -> 0.10948847 | F9: 67.17076 | G9: =F9/$F$8 -> 1.0899238 | H9: 69.091072 | I9: =H9/F9-1 -> 0.028588511 | J9: CHƯA ĐO | K9: CHƯA ĐO | L9: =(B8-B9)*8/(F9-F8) -> 41743.085 | M9: ✓
A10: 128 | B10: 240733 | C10: =$B$3/B10 -> 4.1539797 | D10: =B10/$B$3 -> 0.240733 | E10: =C10/$C$8-1 -> 0.21722822 | F10: 82.953516 | G10: =F10/$F$8 -> 1.3460174 | H10: 88.830186 | I10: =H10/F10-1 -> 0.070842928 | J10: CHƯA ĐO | K10: CHƯA ĐO | L10: =(B9-B10)*8/(F10-F9) -> 11849.388 | M10: ✓
A11: 256 | B11: 222510 | C11: =$B$3/B11 -> 4.49418 | D11: =B11/$B$3 -> 0.22251 | E11: =C11/$C$8-1 -> 0.31691609 | F11: 114.33282 | G11: =F11/$F$8 -> 1.8551831 | H11: 124.82986 | I11: =H11/F11-1 -> 0.091811321 | J11: CHƯA ĐO | K11: CHƯA ĐO | L11: =(B10-B11)*8/(F11-F10) -> 4645.865 | M11: ✓
A12: 512 | B12: 208720 | C12: =$B$3/B12 -> 4.7911077 | D12: =B12/$B$3 -> 0.20872 | E12: =C12/$C$8-1 -> 0.40392392 | F12: 178.8173 | G12: =F12/$F$8 -> 2.9015189 | H12: 199.04195 | I12: =H12/F12-1 -> 0.1131023 | J12: CHƯA ĐO | K12: CHƯA ĐO | L12: =(B11-B12)*8/(F12-F11) -> 1710.7991 | M12: ✓
A13: Cột L = số bit tiết kiệm được cho mỗi giây tính thêm khi tăng context lên mức này. Đây chính là thang đo cho tham số λ của DPPolicy (adaptive_context_finezip.py): λ > giá trị ở hàng nào thì chính sách sẽ KHÔNG chọn lên mức đó.
A14: Hai lần đo thời gian (cột F và H) khác nhau 3–11%: chưa rõ nguyên nhân (khác phiên Kaggle / cách đo). Báo cáo dùng cột F (truy được tới notebook), ghi rõ sai số.
A16: B. LLMZip-lite (arithmetic coding, cửa sổ trượt, batch 1)
A17: Context (cửa sổ trượt) | B17: AC bits | C17: Compressed (B) = ROUNDUP(bits/8) | D17: Ratio (gốc/nén) | E17: Compressed % | F17: Bits/char | G17: Enc (s) | H17: Thời gian × so với ctx 32 | I17: Dec (s) | J17: Bit tiết kiệm / giây thêm | K17: Lossless
A18: 32 | B18: 1494873 | C18: =ROUNDUP(B18/8,0) -> 186860 | D18: =$B$3/C18 -> 5.3516001 | E18: =C18/$B$3 -> 0.18686 | F18: =B18/$B$4 -> 1.5012262 | G18: 2938.72 | H18: =G18/$G$18 -> 1 | I18: =GD2_Baseline!L10 -> 2851.32 | J18: - | K18: ✓
A19: 64 | B19: 1349477 | C19: =ROUNDUP(B19/8,0) -> 168685 | D19: =$B$3/C19 -> 5.9282094 | E19: =C19/$B$3 -> 0.168685 | F19: =B19/$B$4 -> 1.3552123 | G19: 3072.81 | H19: =G19/$G$18 -> 1.0456287 | I19: CHƯA ĐO | J19: =(B18-B19)/(G19-G18) -> 1084.3165 | K19: ✓
A20: 128 | B20: 1254847 | C20: =ROUNDUP(B20/8,0) -> 156856 | D20: =$B$3/C20 -> 6.3752741 | E20: =C20/$B$3 -> 0.156856 | F20: =B20/$B$4 -> 1.2601801 | G20: 3504.67 | H20: =G20/$G$18 -> 1.1925838 | I20: CHƯA ĐO | J20: =(B19-B20)/(G20-G19) -> 219.12194 | K20: ✓
A21: 256 | B21: 1164161 | C21: =ROUNDUP(B21/8,0) -> 145521 | D21: =$B$3/C21 -> 6.8718604 | E21: =C21/$B$3 -> 0.145521 | F21: =B21/$B$4 -> 1.1691087 | G21: 6381.51 | H21: =G21/$G$18 -> 2.1715271 | I21: CHƯA ĐO | J21: =(B20-B21)/(G21-G20) -> 31.522782 | K21: ✓
A22: 512 | B22: 1138347 | C22: =ROUNDUP(B22/8,0) -> 142294 | D22: =$B$3/C22 -> 7.0277032 | E22: =C22/$B$3 -> 0.142294 | F22: =B22/$B$4 -> 1.143185 | G22: 14486.5 | H22: =G22/$G$18 -> 4.9295271 | I22: CHƯA ĐO | J22: =(B21-B22)/(G22-G21) -> 3.1849515 | K22: ✓
A23: Dec ctx 32 = số đo ở GĐ2 (2851 s ≈ 0.97 × enc). Các ctx còn lại chưa đo; có thể ghi 'ước tính ≈ enc' (dec/enc = 0.97–1.01 ở các lần đo GĐ2) thay vì chạy lại ~4 giờ cho ctx 512.
A25: C. Đặt cạnh nhau (tham khảo — KHÔNG phải cuộc thi trực tiếp, xem ghi chú)
A26: Context | B26: Ratio FineZip | C26: Ratio LLMZip-lite | D26: LLMZip-lite / FineZip (ratio) | E26: Enc FineZip (s) | F26: Enc LLMZip-lite (s) | G26: LLMZip-lite / FineZip (thời gian)
A27: =A8 -> 32 | B27: =C8 -> 3.4126548 | C27: =D18 -> 5.3516001 | D27: =C27/B27 -> 1.5681633 | E27: =F8 -> 61.62886 | F27: =G18 -> 2938.72 | G27: =F27/E27 -> 47.684153
A28: =A9 -> 64 | B28: =C9 -> 3.7863012 | C28: =D19 -> 5.9282094 | D28: =C28/B28 -> 1.5656994 | E28: =F9 -> 67.17076 | F28: =G19 -> 3072.81 | G28: =F28/E28 -> 45.746244
A29: =A10 -> 128 | B29: =C10 -> 4.1539797 | C29: =D20 -> 6.3752741 | D29: =C29/B29 -> 1.5347389 | E29: =F10 -> 82.953516 | F29: =G20 -> 3504.67 | G29: =F29/E29 -> 42.248601
A30: =A11 -> 256 | B30: =C11 -> 4.49418 | C30: =D21 -> 6.8718604 | D30: =C30/B30 -> 1.5290577 | E30: =F11 -> 114.33282 | F30: =G21 -> 6381.51 | G30: =F30/E30 -> 55.815208
A31: =A12 -> 512 | B31: =C12 -> 4.7911077 | C31: =D22 -> 7.0277032 | D31: =C31/B31 -> 1.4668222 | E31: =F12 -> 178.8173 | F31: =G22 -> 14486.5 | G31: =F31/E31 -> 81.012854
A32: Không kết luận 'FineZip kém LLMZip-lite' hay 'nhanh hơn N lần' từ bảng này: khác lược đồ mã hoá (rank+bzip2 vs AC), khác ngữ nghĩa context, khác batch (64 vs 1). Muốn so công bằng cần cùng batch và cùng pipeline mã hoá.

Sheet GD35_LoRA
A1: Giai đoạn 3.5 — LoRA / online memorization (đã sửa)
A2: So sánh đúng cặp: CÙNG pipeline arithmetic coding, cùng cửa sổ trượt, chỉ khác có/không LoRA
A3: Original (B) | B3: =GD2_Baseline!B3 -> 1000000
A4: Chars | B4: =GD2_Baseline!B4 -> 995768
A5: Số tham số LoRA (notebook: trainable params) | B5: 811008
A6: Byte / tham số (fp16) | B6: 2
A7: Byte / tham số (fp32) | B7: 4
A8: Kích thước adapter ĐO THẬT (B) — điền sau khi chạy ls -l | B8: 3253104
A9: Adapter dùng để tính (đo thật nếu có, nếu không = fp16 ước tính) | B9: =IF(ISNUMBER(B8),B8,B5*B6) -> 3253104
A10: Adapter fp32 ước tính (B) | B10: =B5*B7 -> 3244032
A12: 1. LoRA vs không LoRA — cùng pipeline AC
A13: Context | B13: AC bits (không LoRA) | C13: AC bits (LoRA) | D13: Bytes (không LoRA) | E13: Bytes (LoRA) | F13: Ratio (không LoRA) | G13: Ratio (LoRA) | H13: Giảm kích thước nhờ LoRA | I13: Bits/char (không LoRA) | J13: Bits/char (LoRA) | K13: Enc (s) không LoRA | L13: Enc (s) LoRA | M13: Thời gian tăng | N13: Lossless
A14: 128 | B14: =GD3_FixedContext!B20 -> 1254847 | C14: 1201663 | D14: =ROUNDUP(B14/8,0) -> 156856 | E14: =ROUNDUP(C14/8,0) -> 150208 | F14: =$B$3/D14 -> 6.3752741 | G14: =$B$3/E14 -> 6.657435 | H14: =1-E14/D14 -> 0.042382822 | I14: =B14/$B$4 -> 1.2601801 | J14: =C14/$B$4 -> 1.2067701 | K14: =GD3_FixedContext!G20 -> 3504.67 | L14: 4973.2294 | M14: =L14/K14-1 -> 0.41902931 | N14: ✓
A15: 512 | B15: =GD3_FixedContext!B22 -> 1138347 | C15: 1086476 | D15: =ROUNDUP(B15/8,0) -> 142294 | E15: =ROUNDUP(C15/8,0) -> 135810 | F15: =$B$3/D15 -> 7.0277032 | G15: =$B$3/E15 -> 7.363228 | H15: =1-E15/D15 -> 0.045567628 | I15: =B15/$B$4 -> 1.143185 | J15: =C15/$B$4 -> 1.0910935 | K15: =GD3_FixedContext!G22 -> 14486.5 | L15: 16030.615 | M15: =L15/K15-1 -> 0.10658991 | N15: ✓
A16: Bảng gốc đặt FineZip-rank 4.154× cạnh LoRA-AC 6.657× (khác pipeline) nên trông như LoRA cải thiện ~60%. Đúng cặp: LoRA chỉ giảm kích thước khoảng 4–5% (cột H).
A17: LoRA chạy chậm hơn (cột M) vì adapter chưa merge: có thể thử model.merge_and_unload() trước khi nén để bỏ chi phí suy luận thêm. Hai lần đo có thể khác phiên Kaggle → coi là xu hướng.
A19: 2. Tính cả chi phí lưu adapter (phải gửi kèm file nén để giải nén được)
A20: Context | B20: File nén LoRA (B) | C20: + adapter (B) | D20: Ratio ròng (gốc / (nén + adapter)) | E20: bzip2 (B) | F20: Ròng so với bzip2 | G20: Tiết kiệm / 1 MB dữ liệu so với không LoRA (B) | H20: Điểm hoà vốn: dữ liệu gốc cần ≥ (MB)
A21: =A14 -> 128 | B21: =E14 -> 150208 | C21: =B21+$B$9 -> 3403312 | D21: =$B$3/C21 -> 0.29383142 | E21: =GD2_Baseline!$G$9 -> 281323 | F21: =IF(C21<E21,"Tốt hơn","Kém hơn") -> Kém hơn | G21: =D14-E14 -> 6648 | H21: =$B$9/G21*$B$3/1000000 -> 489.33574
A22: =A15 -> 512 | B22: =E15 -> 135810 | C22: =B22+$B$9 -> 3388914 | D22: =$B$3/C22 -> 0.29507978 | E22: =GD2_Baseline!$G$9 -> 281323 | F22: =IF(C22<E22,"Tốt hơn","Kém hơn") -> Kém hơn | G22: =D15-E15 -> 6484 | H22: =$B$9/G22*$B$3/1000000 -> 501.71252
A23: Giả định (nên ghi trong báo cáo): adapter có kích thước cố định; mức tiết kiệm tăng tuyến tính theo dung lượng dữ liệu. Thực tế adapter cố định 'nhớ' được ít hơn trên dữ liệu lớn → điểm hoà vốn thật có thể XA hơn con số này. Ở 1 MB, LoRA không có lợi ròng.
A25: 3. Loss / perplexity (hai phép đo khác tập, KHÔNG so với nhau)
A26: Phép đo | B26: Tập đánh giá | C26: Loss trước | D26: Loss sau | E26: Δ loss | F26: PPL trước | G26: PPL sau | H26: Δ PPL | I26: Ghi chú
A27: Trong script huấn luyện | B27: 559 khối × 512 = 286.208 token (chính là dữ liệu huấn luyện) | C27: 3.0574553 | D27: 2.973362 | E27: =D27/C27-1 -> -0.027504353 | F27: 21.273355 | G27: 19.557562 | H27: =G27/F27-1 -> -0.080654553 | I27: In-sample → đúng ý 'memorization'.
A28: Đánh giá nhanh (ctx 512) | B28: 16.352 token đầu của file | C28: 3.1634791 | D28: 3.0850257 | E28: =D28/C28-1 -> -0.024799742 | F28: 23.652742 | G28: 21.868031 | H28: =G28/F28-1 -> -0.075454753 | I28: Một lát nhỏ; không phải toàn bộ 286.273 token.
A31: 4. Cấu hình & chi phí huấn luyện LoRA (ĐÃ CÓ trong notebook versionn3_5_1, ô 115 — Excel cũ ghi 'chưa có')
A32: Mô hình / target | B32: GPT-2 · c_attn, c_proj
A33: r / alpha / dropout | B33: 8 / 16 / 0.05
A34: Epoch · batch · grad accum · lr | B34: 1 · 2 · 4 · 2e-4
A35: Thời gian huấn luyện (s) | B35: 48.614301
A36: Peak GPU allocated (MiB) | B36: 2749.2373
A37: Peak GPU reserved (MiB) | B37: 3024
A38: Tham số huấn luyện / tổng | B38: 811,008 / 125,250,816 (0.6475%)

Sheet CanChayLai
A1: Có bắt buộc chạy lại không?
A2: Ngắn gọn: KHÔNG cần chạy lại để sửa các bảng. Chỉ có vài việc bổ sung nhỏ (cột 'Mức độ').
A3: # | B3: Việc | C3: Mức độ | D3: Vì sao | E3: Chi phí ước tính | F3: Cách làm
A4: 1 | B4: Sửa bytes/ratio LLMZip-lite, chuẩn hoá ratio, cặp so sánh LoRA, cộng adapter | C4: Không cần chạy lại | D4: Chỉ là tính lại từ số đã có (đã làm trong file này). | E4: 0 | F4: —
A5: 2 | B5: Đo kích thước adapter thật | C5: ĐÃ XONG — adapter = 3,253,104 B (điền ở GD35_LoRA!B8) | D5: Hiện chỉ ước tính 1.6–3.2 MB. Số thật làm bảng 'hoà vốn' chính xác. | E5: < 1 phút | F5: !ls -l /kaggle/working/finezip_experiment/lora_gpt2_1mb → điền vào GD35_LoRA!B8 | G5: 3,253,104 bytes (≈3.10 MiB)
A6: 3 | B6: FineZip: thời gian GIẢI NÉN và GPU peak cho 5 context (bs 64) | C6: Đã đo cho Adaptive λ=1000 (dec + GPU peak). FineZip fixed vẫn CHƯA đo | D6: Đang thiếu; decode tự hồi quy có thể nặng hơn encode, và DPPolicy cần mô hình thời gian đúng. | E6: Chưa biết chính xác (chưa từng đo decode ở bs 64); ước tính vài chục phút | F6: Gọi unzip/decompress có bọc time.perf_counter(); reset_peak_memory_stats() trước mỗi lần. Gộp luôn việc chốt lại thời gian enc (dòng dưới).
A7: 4 | B7: Chốt lại thời gian enc FineZip (2 lần đo lệch 3–11%) | C7: Tuỳ chọn | D7: Không đổi kết luận; có thể chỉ ghi sai số. | E7: ~10 phút nếu gộp với việc trên | F7: Chạy lại 5 ctx 1 lần, lấy trung bình.
A8: 5 | B8: LLMZip-lite: dec time cho ctx 64–512 | C8: Không nên chạy | D8: Chạy ctx 512 mất ~4 giờ; dec ≈ enc ở các lần đo (0.97–1.01). | E8: ~8 giờ | F8: Ghi 'ước tính ≈ enc', nói rõ chỉ đo thật ở ctx 32.
A9: 6 | B9: So sánh thời gian công bằng cùng batch | C9: Tuỳ chọn, nên có | D9: Hiện batch 1 vs 64 làm chênh ~45× chỉ do batch. | E9: vài phút/ctx | F9: eval_ac.py --batch_size 64 (nếu hỗ trợ như README mô tả); ghi rõ kích thước file có thể tăng nhẹ do nhiều luồng AC.
A10: 7 | B10: LoRA cho pipeline FineZip thật (rank + bzip2) | C10: Nên làm | D10: Hiện LoRA mới chạy với AC; 'FineZip' trong paper là rank+bzip2+LoRA. | E10: vài phút/ctx | F10: Repo có nhánh finetuned_models trong memory_eval(); nạp PeftModel rồi chạy ctx 128/512.
A11: 8 | B11: Dữ liệu thứ hai / lát khác của enwik8 | C11: Bắt buộc cho GĐ5 | D11: Adaptive chỉ có ý nghĩa khi văn bản không đồng nhất; 1 lát 1 MB chưa đủ kết luận. | E11: — | F11: Ghép wiki + code + bảng số, hoặc lát 5–10 MB.
A12: 9 | B12: GĐ4–5: Adaptive Context, Fixed vs Adaptive, ablation | C12: GĐ4 XONG (λ=1000 lossless đầy đủ). GĐ5 chưa làm | D12: Đây là đóng góp riêng. | E12: Prototype trên Kaggle, bản cuối trên 4090 | F12: Xem adaptive_context_finezip.py và sheet GD5_MauBang.

Sheet GD4_KetQua
A1: Giai đoạn 4 — Adaptive Context (DP trên cây chunk) · 1 MB enwik8 · GPT-2 · Kaggle T4
A2: Nguồn: adaptive_results_v3_final.json và các lần chạy trước. Xanh dương = số đo; đen = công thức; xanh lá = liên kết sheet.
A3: Token (GPT-2) | B3: =GD2_Baseline!B5 -> 286273
I4: L → | J4: 32 | K4: 64 | L4: 128 | M4: 256 | N4: 512
A5: A. Kết quả cuối (codec v3, không escape, batch plan lưu trong header)
A6: Cấu hình | B6: Codec | C6: Compressed (B) | D6: Ratio (gốc/nén) | E6: Header (B) | F6: Enc tổng (s) | G6: Dec (s) | H6: GPU peak dec (MiB) | I6: Kiểm tra lossless | J6: n32 | K6: n64 | L6: n128 | M6: n256 | N6: n512 | O6: Σ n·L² | P6: L̄ theo token | Q6: Dec ước tính — thấp (s) | R6: Dec ước tính — cao (s) | S6: Ghi chú
A7: λ=1000 | B7: v3 | C7: 216534 | D7: =GD2_Baseline!$B$3/C7 -> 4.6182124 | E7: 278 | F7: 201.73223 | G7: 12000.909 | H7: 817.9292 | I7: ĐÚNG ✓ (decode đầy đủ) | J7: 1 | K7: 17 | L7: 50 | M7: 397 | N7: 346 | O7: =SUMPRODUCT(J7:N7,$J$4:$N$4^2) -> 117609472 | P7: =O7/SUMPRODUCT(J7:N7,$J$4:$N$4) -> 410.78529 | S7: Cấu hình cuối của GĐ4.
A8: λ=5000 | B8: v3 | C8: 238128 | D8: =GD2_Baseline!$B$3/C8 -> 4.1994222 | E8: 602 | F8: 195.81413 | G8: CHƯA ĐO | H8: CHƯA ĐO | I8: quick_check OK (3 nhóm/mức L) | J8: 39 | K8: 380 | L8: 1401 | M8: 292 | N8: 13 | O8: =SUMPRODUCT(J8:N8,$J$4:$N$4^2) -> 47094784 | P8: =O8/SUMPRODUCT(J8:N8,$J$4:$N$4) -> 164.49223 | Q8: =$P$25*O8/100000 -> 3810.2716 | R8: =$P$26*O8/100000 -> 4805.5672 | S8: Bản v1 cùng layout đã giải nén đúng đầy đủ (4.605,5 s).
A9: λ=12000 | B9: v3 | C9: 258127 | D9: =GD2_Baseline!$B$3/C9 -> 3.874062 | E9: 1001 | F9: 200.77725 | G9: CHƯA ĐO | H9: CHƯA ĐO | I9: quick_check OK (3 nhóm/mức L) | J9: 563 | K9: 2694 | L9: 703 | M9: 23 | N9: 0 | O9: =SUMPRODUCT(J9:N9,$J$4:$N$4^2) -> 24636416 | P9: =O9/SUMPRODUCT(J9:N9,$J$4:$N$4) -> 86.049849 | Q9: =$P$25*O9/100000 -> 1993.2449 | R9: =$P$26*O9/100000 -> 2513.908
A10: λ=40000 | B10: v3 | C10: 288012 | D10: =GD2_Baseline!$B$3/C10 -> 3.4720776 | E10: 1193 | F10: 201.60596 | G10: CHƯA ĐO | H10: CHƯA ĐO | I10: quick_check OK (3 nhóm/mức L) | J10: 6735 | K10: 1100 | L10: 3 | M10: 0 | N10: 0 | O10: =SUMPRODUCT(J10:N10,$J$4:$N$4^2) -> 11451392 | P10: =O10/SUMPRODUCT(J10:N10,$J$4:$N$4) -> 39.997318 | Q10: =$P$25*O10/100000 -> 926.49143 | R10: =$P$26*O10/100000 -> 1168.5038
A11: Enc tổng = chấm điểm 5 mức L cho DP + 1 lượt tính rank (đo bằng perf_counter). Gần như hằng theo λ nên KHÔNG dùng để so tốc độ với Fixed; cần tách 'phân tích' và 'mã hoá'. Cột Q–R (xám nghiêng) chỉ là ước tính thô theo mô hình c·Σn·L² với c lấy từ khoảng min–max của các lần giải nén đúng ở mục B.
A13: B. Nhật ký MỌI lần giải nén đầy đủ
A14: Run | B14: Codec | G14: Dec (s) | H14: GPU peak dec (MiB) | I14: Kết quả | J14: n32 | K14: n64 | L14: n128 | M14: n256 | N14: n512 | O14: Σ n·L² | P14: Dec / Σn·L² (×1e-5 s) | S14: Ghi chú
A15: λ=1000 | B15: v1 (không escape) | G15: 9414.8661 | H15: 768.53711 | I15: SAI ✗ | J15: 1 | K15: 17 | L15: 50 | M15: 397 | N15: 346 | O15: =SUMPRODUCT(J15:N15,$J$4:$N$4^2) -> 117609472 | P15: =G15/O15*100000 -> 8.0051937 | S15: Rank lệch theo nhóm batch; blob không hợp lệ.
A16: λ=1000 | B16: v2 + escape, eps=0.20 | G16: 9515.3644 | H16: 767.91211 | I16: ĐÚNG ✓ | J16: 1 | K16: 17 | L16: 50 | M16: 397 | N16: 346 | O16: =SUMPRODUCT(J16:N16,$J$4:$N$4^2) -> 117609472 | P16: =G16/O16*100000 -> 8.0906446 | S16: 44,2% token bị escape (+27% kích thước).
A17: λ=1000 | B17: v2 + escape, eps=0.152 | G17: 9518.135 | H17: 767.91211 | I17: ĐÚNG ✓ | J17: 1 | K17: 17 | L17: 50 | M17: 397 | N17: 346 | O17: =SUMPRODUCT(J17:N17,$J$4:$N$4^2) -> 117609472 | P17: =G17/O17*100000 -> 8.0930003 | S17: 41,6% escape.
A18: λ=1000 | B18: v3, phiên Kaggle 1 | G18: 9523.1055 | H18: 768.77441 | I18: ĐÚNG ✓ | J18: 1 | K18: 17 | L18: 50 | M18: 397 | N18: 346 | O18: =SUMPRODUCT(J18:N18,$J$4:$N$4^2) -> 117609472 | P18: =G18/O18*100000 -> 8.0972266 | S18: Cùng kích thước blob 216.534 B.
A19: λ=1000 | B19: v3, phiên Kaggle 2 (cuối) | G19: 12000.909 | H19: 817.9292 | I19: ĐÚNG ✓ | J19: 1 | K19: 17 | L19: 50 | M19: 397 | N19: 346 | O19: =SUMPRODUCT(J19:N19,$J$4:$N$4^2) -> 117609472 | P19: =G19/O19*100000 -> 10.204033 | S19: Chậm hơn 26% cùng blob; nguyên nhân CHƯA xác định (nghi GPU/phiên khác).
A20: λ=5000 | B20: v1 (không escape) | G20: 4605.5308 | H20: 777.25635 | I20: ĐÚNG ✓ | J20: 39 | K20: 380 | L20: 1401 | M20: 292 | N20: 13 | O20: =SUMPRODUCT(J20:N20,$J$4:$N$4^2) -> 47094784 | P20: =G20/O20*100000 -> 9.7792801
A22: Biến động dec λ=1000 giữa hai phiên v3 | G22: =G19/G18-1 -> 0.2601886
A23: Biến động GPU peak giữa hai phiên v3 (MiB) | G23: =H19-H18 -> 49.154785
A24: Lần đầu mình nói thời gian giải nén 'ổn định ±1,2%' — đúng trong MỘT phiên (9.415–9.523 s) nhưng phiên sau chậm hơn 26% với cùng blob. Báo cáo nên ghi khoảng giá trị và nêu rõ chưa kiểm soát GPU.
A25: c thấp = MIN (các lần ĐÚNG) | P25: =MIN(P16:P20) -> 8.0906446
A26: c cao = MAX (các lần ĐÚNG) | P26: =MAX(P16:P20) -> 10.204033
A28: C. Escape (thử nghiệm đã loại bỏ): chi phí so với codec v3 không escape
A29: Run | B29: eps | C29: Compressed (B) | D29: Escape | E29: % token | F29: Byte phần escape | G29: Bit / escape | H29: Phụ phí so với v3 (B) | I29: Phụ phí (%)
A30: v2 eps=0.20 | B30: 0.201931 | C30: 275748 | D30: 126515 | E30: =D30/$B$3 -> 0.44193829 | F30: 246453 | G30: =F30*8/D30 -> 15.584113 | H30: =C30-$C$7 -> 59214 | I30: =C30/$C$7-1 -> 0.27346283
A31: v2 eps=0.152 | B31: 0.15193939 | C31: 271367 | D31: 119152 | E31: =D31/$B$3 -> 0.41621809 | F31: 236358 | G31: =F31*8/D31 -> 15.869343 | H31: =C31-$C$7 -> 54833 | I31: =C31/$C$7-1 -> 0.25323044
A32: Kết luận: nhiễu logit giữa các batch ~0,02 → eps phải ≥ 0,15 → ~40% token bị escape (≈15,6 bit/escape, đắt gấp ~2,6 lần rank bình thường). Escape chỉ đáng dùng nếu cần giải nén trên MÁY KHÁC; cùng máy thì giữ nguyên kế hoạch batch (v3) là đủ.
A34: ⚠ MỤC D CŨ ĐÃ BỊ GỠ: nó so Adaptive (codec v3) với Fixed của GĐ3 (codec khác, nhỏ hơn ~2,6%) nên cho kết luận SAI CHIỀU ('Adaptive kém Fixed 1,5%'). Phép so đúng, cùng codec v3, nằm ở sheet GD5_SoSanh.

Sheet GD5_SoSanh
A1: Giai đoạn 5 — Fixed vs Adaptive CÙNG codec v3, cùng chi phí giải nén (GPT-2 · 1 MB enwik8 · Kaggle T4)
A2: Nguồn: version4_2.ipynb (cells 7–14). Chi phí giải nén mô hình hoá là c·L² mỗi chunk ⇒ cả file ∝ Σn·L²; L̄ = Σn·L² / Σn·L là độ dài chunk 'tương đương' (Fixed-L có L̄ = L).
A4: Dec λ=1000, phiên 2 (s) | B4: 12000.909
A5: Dec λ=1000, phiên 1 (s) | B5: 9523.1055
A6: Σ n·L² của λ=1000 | B6: 117609472
A7: c chậm (s / đơn vị Σn·L²) | B7: =B4/B6 -> 0.00010204033
A8: c nhanh (phiên 1) | B8: =B5/B6 -> 8.0972266e-05
A9: Σ n·L (token đã đệm) | B9: 286304
A11: A. Fixed (codec v3)
A12: Policy | B12: Mục tiêu / codec | C12: Compressed (B) | D12: Ratio (gốc/nén) | E12: Header (B) | F12: Enc (s) | G12: Σ n·L² | H12: L̄ | I12: Dec ước tính, c chậm (s) | J12: Dec ước tính, c nhanh (s) | K12: quick_check | L12: Ghi chú
A13: Fixed-32 | B13: FixedPolicy | C13: 300576 | D13: =GD2_Baseline!$B$3/C13 -> 3.3269456 | E13: 1194 | F13: 27.989156 | G13: 9161728 | H13: =G13/$B$9 -> 32 | I13: =$B$7*G13 -> 934.86573 | J13: =$B$8*G13 -> 741.84588 | K13: OK (mẫu)
A14: Fixed-64 | B14: FixedPolicy | C14: 271704 | D14: =GD2_Baseline!$B$3/C14 -> 3.6804758 | E14: 1194 | F14: 28.5322 | G14: 18322432 | H14: =G14/$B$9 -> 63.996423 | I14: =$B$7*G14 -> 1869.627 | J14: =$B$8*G14 -> 1483.6088 | K14: OK (mẫu)
A15: Fixed-128 | B15: FixedPolicy | C15: 246976 | D15: =GD2_Baseline!$B$3/C15 -> 4.0489764 | E15: 635 | F15: 26.494509 | G15: 36639744 | H15: =G15/$B$9 -> 127.97496 | I15: =$B$7*G15 -> 3738.7315 | J15: =$B$8*G15 -> 2966.8031 | K15: OK (mẫu)
A16: Fixed-256 | B16: FixedPolicy | C16: 228006 | D16: =GD2_Baseline!$B$3/C16 -> 4.3858495 | E16: 355 | F16: 27.012356 | G16: 73274368 | H16: =G16/$B$9 -> 255.93204 | I16: =$B$7*G16 -> 7476.9405 | J16: =$B$8*G16 -> 5933.1917 | K16: OK (mẫu)
A17: Fixed-512 | B17: FixedPolicy | C17: 213691 | D17: =GD2_Baseline!$B$3/C17 -> 4.6796543 | E17: 215 | F17: 27.533378 | G17: 146543616 | H17: =G17/$B$9 -> 511.84621 | I17: =$B$7*G17 -> 14953.359 | J17: =$B$8*G17 -> 11865.969 | K17: OK (mẫu)
A19: B. Adaptive-DP (codec v3). 'DP-bits' = mục tiêu cũ (bit AC + λ·thời gian nén); 'DP-decode' = bit AC + λ·c·L²
A20: Policy | B20: Mục tiêu / codec | C20: Compressed (B) | D20: Ratio (gốc/nén) | E20: Header (B) | F20: Enc (s) | G20: Σ n·L² | H20: L̄ | I20: Dec ước tính, c chậm (s) | J20: Dec ước tính, c nhanh (s) | K20: quick_check | L20: Ghi chú
A21: Adaptive λ=1000 | B21: DP-bits | C21: 216534 | D21: =GD2_Baseline!$B$3/C21 -> 4.6182124 | E21: 278 | F21: 160.46178 | G21: 117609472 | H21: =G21/$B$9 -> 410.78529 | I21: =$B$7*G21 -> 12000.909 | J21: =$B$8*G21 -> 9523.1055 | K21: ĐÚNG ✓ (đầy đủ) | L21: Dec đo thật: 12.000,9 s (phiên 2); 9.523 s (phiên 1).
A22: Adaptive λ=5000 | B22: DP-bits | C22: 238128 | D22: =GD2_Baseline!$B$3/C22 -> 4.1994222 | E22: 602 | F22: 163.27003 | G22: 47094784 | H22: =G22/$B$9 -> 164.49223 | I22: =$B$7*G22 -> 4805.5672 | J22: =$B$8*G22 -> 3813.3714 | K22: OK (mẫu)
A23: Adaptive λ=12000 | B23: DP-bits | C23: 258127 | D23: =GD2_Baseline!$B$3/C23 -> 3.874062 | E23: 1001 | F23: 163.87637 | G23: 24636416 | H23: =G23/$B$9 -> 86.049849 | I23: =$B$7*G23 -> 2513.908 | J23: =$B$8*G23 -> 1994.8664 | K23: OK (mẫu)
A24: Adaptive λ=40000 | B24: DP-bits | C24: 288012 | D24: =GD2_Baseline!$B$3/C24 -> 3.4720776 | E24: 1193 | F24: 164.63667 | G24: 11451392 | H24: =G24/$B$9 -> 39.997318 | I24: =$B$7*G24 -> 1168.5038 | J24: =$B$8*G24 -> 927.24516 | K24: OK (mẫu)
A25: Adaptive λ=100 | B25: DP-decode | C25: 257940 | D25: =GD2_Baseline!$B$3/C25 -> 3.8768706 | E25: 995 | F25: 164.29102 | G25: 24869888 | H25: =G25/$B$9 -> 86.865318 | I25: =$B$7*G25 -> 2537.7315 | J25: =$B$8*G25 -> 2013.7712 | K25: OK (mẫu) | L25: Cùng vùng L̄ với DP-bits λ=12000.
A26: Adaptive λ=300 | B26: DP-decode | C26: 284591 | D26: =GD2_Baseline!$B$3/C26 -> 3.5138146 | E26: 1188 | F26: 164.26789 | G26: 12372992 | H26: =G26/$B$9 -> 43.216274 | I26: =$B$7*G26 -> 1262.5442 | J26: =$B$8*G26 -> 1001.8692 | K26: OK (mẫu)
A27: Adaptive λ=1000 | B27: DP-decode | C27: 300358 | D27: =GD2_Baseline!$B$3/C27 -> 3.3293603 | E27: 1194 | F27: 164.42521 | G27: 9178112 | H27: =G27/$B$9 -> 32.057226 | I27: =$B$7*G27 -> 936.53755 | J27: =$B$8*G27 -> 743.17253 | K27: OK (mẫu) | L27: ≈ Fixed-32.
A28: Adaptive λ=3000 | B28: DP-decode | C28: 300576 | D28: =GD2_Baseline!$B$3/C28 -> 3.3269456 | E28: 1194 | F28: 164.60072 | G28: 9161728 | H28: =G28/$B$9 -> 32 | I28: =$B$7*G28 -> 934.86573 | J28: =$B$8*G28 -> 741.84588 | K28: OK (mẫu) | L28: Suy biến thành Fixed-32.
A29: Adaptive λ=10000 | B29: DP-decode | C29: 300576 | D29: =GD2_Baseline!$B$3/C29 -> 3.3269456 | E29: 1194 | F29: 165.12609 | G29: 9161728 | H29: =G29/$B$9 -> 32 | I29: =$B$7*G29 -> 934.86573 | J29: =$B$8*G29 -> 741.84588 | K29: OK (mẫu) | L29: Suy biến thành Fixed-32.
A30: Cột I–J (xám nghiêng) chỉ là ước tính theo mô hình c·Σn·L²; c dao động 8,1–10,2 (×1e-5 s) giữa các phiên. CẦN đo t_dec(L) thật trong cùng phiên (xem bước tiếp theo).
A32: C. Ở CÙNG L̄ (cùng chi phí giải nén theo mô hình): Adaptive nhỏ hơn Fixed bao nhiêu?
A33: Adaptive | B33: L̄ | C33: Compressed (B) | D33: Fixed tại L̄ — chia sẻ thời gian (tuyến tính theo L̄) | E33: Δ% | F33: Fixed tại L̄ — nội suy log₂ (dây cung) | G33: Δ% | H33: Fixed tại L̄ — đường cong bậc 2 (ước lượng tốt nhất) | I33: Δ% | J33: L tương đương KÍCH THƯỚC (dây cung) | K33: Tiết kiệm giải nén (dây cung) | L33: L tương đương KÍCH THƯỚC (chia sẻ thời gian) | M33: Tiết kiệm giải nén (chia sẻ thời gian) | N33: Ghi chú
A34: λ=1000 DP-bits | B34: =H21 -> 410.78529 | C34: =C21 -> 216534 | D34: =$C$16+(B34-$H$16)/($H$17-$H$16)*($C$17-$C$16) -> 219344.02 | E34: =C34/D34-1 -> -0.012811002 | F34: =$C$16+(LOG(B34,2)-LOG($H$16,2))/(LOG($H$17,2)-LOG($H$16,2))*($C$17-$C$16) -> 218233.75 | G34: =C34/F34-1 -> -0.0077886611 | H34: =$C$15*(LOG(B34,2)-LOG($H$16,2))*(LOG(B34,2)-LOG($H$17,2))/((LOG($H$15,2)-LOG($H$16,2))*(LOG($H$15,2)-LOG($H$17,2)))+$C$16*(LOG(B34,2)-LOG($H$15,2))*(LOG(B34,2)-LOG($H$17,2))/((LOG($H$16,2)-LOG($H$15,2))*(LOG($H$16,2)-LOG($H$17,2)))+$C$17*(LOG(B34,2)-LOG($H$15,2))*(LOG(B34,2)-LOG($H$16,2))/((LOG($H$17,2)-LOG($H$15,2))*(LOG($H$17,2)-LOG($H$16,2))) -> 217729.41 | I34: =C34/H34-1 -> -0.0054903567 | J34: =2^(LOG($H$16,2)+($C$16-C34)/($C$16-$C$17)*(LOG($H$17,2)-LOG($H$16,2))) -> 446.02282 | K34: =1-B34/J34 -> 0.079003876 | L34: =$H$16+($C$16-C34)/($C$16-$C$17)*($H$17-$H$16) -> 461.02092 | M34: =1-B34/L34 -> 0.10896605
A35: λ=5000 DP-bits | B35: =H22 -> 164.49223 | C35: =C22 -> 238128 | D35: =$C$15+(B35-$H$15)/($H$16-$H$15)*($C$16-$C$15) -> 241562.21 | E35: =C35/D35-1 -> -0.014216675 | F35: =$C$15+(LOG(B35,2)-LOG($H$15,2))/(LOG($H$16,2)-LOG($H$15,2))*($C$16-$C$15) -> 240105.17 | G35: =C35/F35-1 -> -0.0082346115 | H35: =$C$14*(LOG(B35,2)-LOG($H$15,2))*(LOG(B35,2)-LOG($H$16,2))/((LOG($H$14,2)-LOG($H$15,2))*(LOG($H$14,2)-LOG($H$16,2)))+$C$15*(LOG(B35,2)-LOG($H$14,2))*(LOG(B35,2)-LOG($H$16,2))/((LOG($H$15,2)-LOG($H$14,2))*(LOG($H$15,2)-LOG($H$16,2)))+$C$16*(LOG(B35,2)-LOG($H$14,2))*(LOG(B35,2)-LOG($H$15,2))/((LOG($H$16,2)-LOG($H$14,2))*(LOG($H$16,2)-LOG($H$15,2))) -> 239439.77 | I35: =C35/H35-1 -> -0.0054785163 | J35: =2^(LOG($H$15,2)+($C$15-C35)/($C$15-$C$16)*(LOG($H$16,2)-LOG($H$15,2))) -> 176.81433 | K35: =1-B35/J35 -> 0.069689502 | L35: =$H$15+($C$15-C35)/($C$15-$C$16)*($H$16-$H$15) -> 187.65679 | M35: =1-B35/L35 -> 0.12344109
A36: λ=12000 DP-bits | B36: =H23 -> 86.049849 | C36: =C23 -> 258127 | D36: =$C$14+(B36-$H$14)/($H$15-$H$14)*($C$15-$C$14) -> 263180.25 | E36: =C36/D36-1 -> -0.019200717 | F36: =$C$14+(LOG(B36,2)-LOG($H$14,2))/(LOG($H$15,2)-LOG($H$14,2))*($C$15-$C$14) -> 261138.53 | G36: =C36/F36-1 -> -0.011532304 | H36: =$C$13*(LOG(B36,2)-LOG($H$14,2))*(LOG(B36,2)-LOG($H$15,2))/((LOG($H$13,2)-LOG($H$14,2))*(LOG($H$13,2)-LOG($H$15,2)))+$C$14*(LOG(B36,2)-LOG($H$13,2))*(LOG(B36,2)-LOG($H$15,2))/((LOG($H$14,2)-LOG($H$13,2))*(LOG($H$14,2)-LOG($H$15,2)))+$C$15*(LOG(B36,2)-LOG($H$13,2))*(LOG(B36,2)-LOG($H$14,2))/((LOG($H$15,2)-LOG($H$13,2))*(LOG($H$15,2)-LOG($H$14,2))) -> 260631.95 | I36: =C36/H36-1 -> -0.0096110542 | J36: =2^(LOG($H$14,2)+($C$14-C36)/($C$14-$C$15)*(LOG($H$15,2)-LOG($H$14,2))) -> 93.627627 | K36: =1-B36/J36 -> 0.080935281 | L36: =$H$14+($C$14-C36)/($C$14-$C$15)*($H$15-$H$14) -> 99.124078 | M36: =1-B36/L36 -> 0.13189761
A37: λ=40000 DP-bits | B37: =H24 -> 39.997318 | C37: =C24 -> 288012 | D37: =$C$13+(B37-$H$13)/($H$14-$H$13)*($C$14-$C$13) -> 293359.61 | E37: =C37/D37-1 -> -0.018228868 | F37: =$C$13+(LOG(B37,2)-LOG($H$13,2))/(LOG($H$14,2)-LOG($H$13,2))*($C$14-$C$13) -> 291283.34 | G37: =C37/F37-1 -> -0.01123077 | H37: =$C$13*(LOG(B37,2)-LOG($H$14,2))*(LOG(B37,2)-LOG($H$15,2))/((LOG($H$13,2)-LOG($H$14,2))*(LOG($H$13,2)-LOG($H$15,2)))+$C$14*(LOG(B37,2)-LOG($H$13,2))*(LOG(B37,2)-LOG($H$15,2))/((LOG($H$14,2)-LOG($H$13,2))*(LOG($H$14,2)-LOG($H$15,2)))+$C$15*(LOG(B37,2)-LOG($H$13,2))*(LOG(B37,2)-LOG($H$14,2))/((LOG($H$15,2)-LOG($H$13,2))*(LOG($H$15,2)-LOG($H$14,2))) -> 290831.39 | I37: =C37/H37-1 -> -0.0096942423 | J37: =2^(LOG($H$13,2)+($C$13-C37)/($C$13-$C$14)*(LOG($H$14,2)-LOG($H$13,2))) -> 43.264955 | K37: =1-B37/J37 -> 0.075526204 | L37: =$H$13+($C$13-C37)/($C$13-$C$14)*($H$14-$H$13) -> 45.923631 | M37: =1-B37/L37 -> 0.12904714
A38: λ=100 DP-decode | B38: =H25 -> 86.865318 | C38: =C25 -> 257940 | D38: =$C$14+(B38-$H$14)/($H$15-$H$14)*($C$15-$C$14) -> 262865.07 | E38: =C38/D38-1 -> -0.018736103 | F38: =$C$14+(LOG(B38,2)-LOG($H$14,2))/(LOG($H$15,2)-LOG($H$14,2))*($C$15-$C$14) -> 260801.97 | G38: =C38/F38-1 -> -0.010973736 | H38: =$C$13*(LOG(B38,2)-LOG($H$14,2))*(LOG(B38,2)-LOG($H$15,2))/((LOG($H$13,2)-LOG($H$14,2))*(LOG($H$13,2)-LOG($H$15,2)))+$C$14*(LOG(B38,2)-LOG($H$13,2))*(LOG(B38,2)-LOG($H$15,2))/((LOG($H$14,2)-LOG($H$13,2))*(LOG($H$14,2)-LOG($H$15,2)))+$C$15*(LOG(B38,2)-LOG($H$13,2))*(LOG(B38,2)-LOG($H$14,2))/((LOG($H$15,2)-LOG($H$13,2))*(LOG($H$15,2)-LOG($H$14,2))) -> 260291.68 | I38: =C38/H38-1 -> -0.0090347713 | J38: =2^(LOG($H$14,2)+($C$14-C38)/($C$14-$C$15)*(LOG($H$15,2)-LOG($H$14,2))) -> 94.119591 | K38: =1-B38/J38 -> 0.077075061 | L38: =$H$14+($C$14-C38)/($C$14-$C$15)*($H$15-$H$14) -> 99.607901 | M38: =1-B38/L38 -> 0.12792744
A39: λ=300 DP-decode | B39: =H26 -> 43.216274 | C39: =C26 -> 284591 | D39: =$C$13+(B39-$H$13)/($H$14-$H$13)*($C$14-$C$13) -> 290454.99 | E39: =C39/D39-1 -> -0.020188966 | F39: =$C$13+(LOG(B39,2)-LOG($H$13,2))/(LOG($H$14,2)-LOG($H$13,2))*($C$14-$C$13) -> 288058.9 | G39: =C39/F39-1 -> -0.012038853 | H39: =$C$13*(LOG(B39,2)-LOG($H$14,2))*(LOG(B39,2)-LOG($H$15,2))/((LOG($H$13,2)-LOG($H$14,2))*(LOG($H$13,2)-LOG($H$15,2)))+$C$14*(LOG(B39,2)-LOG($H$13,2))*(LOG(B39,2)-LOG($H$15,2))/((LOG($H$14,2)-LOG($H$13,2))*(LOG($H$14,2)-LOG($H$15,2)))+$C$15*(LOG(B39,2)-LOG($H$13,2))*(LOG(B39,2)-LOG($H$14,2))/((LOG($H$15,2)-LOG($H$13,2))*(LOG($H$15,2)-LOG($H$14,2))) -> 287550.39 | I39: =C39/H39-1 -> -0.010291719 | J39: =2^(LOG($H$13,2)+($C$13-C39)/($C$13-$C$14)*(LOG($H$14,2)-LOG($H$13,2))) -> 46.96799 | K39: =1-B39/J39 -> 0.07987816 | L39: =$H$13+($C$13-C39)/($C$13-$C$14)*($H$14-$H$13) -> 49.714839 | M39: =1-B39/L39 -> 0.13071681
A40: λ=1000 DP-decode | B40: =H27 -> 32.057226 | C40: =C27 -> 300358 | D40: =$C$13+(B40-$H$13)/($H$14-$H$13)*($C$14-$C$13) -> 300524.36 | E40: =C40/D40-1 -> -0.000553573 | F40: =$C$13+(LOG(B40,2)-LOG($H$13,2))/(LOG($H$14,2)-LOG($H$13,2))*($C$14-$C$13) -> 300501.57 | G40: =C40/F40-1 -> -0.00047777193 | H40: =$C$13*(LOG(B40,2)-LOG($H$14,2))*(LOG(B40,2)-LOG($H$15,2))/((LOG($H$13,2)-LOG($H$14,2))*(LOG($H$13,2)-LOG($H$15,2)))+$C$14*(LOG(B40,2)-LOG($H$13,2))*(LOG(B40,2)-LOG($H$15,2))/((LOG($H$14,2)-LOG($H$13,2))*(LOG($H$14,2)-LOG($H$15,2)))+$C$15*(LOG(B40,2)-LOG($H$13,2))*(LOG(B40,2)-LOG($H$14,2))/((LOG($H$15,2)-LOG($H$13,2))*(LOG($H$15,2)-LOG($H$14,2))) -> 300496.25 | I40: =C40/H40-1 -> -0.00046006273 | J40: =2^(LOG($H$13,2)+($C$13-C40)/($C$13-$C$14)*(LOG($H$14,2)-LOG($H$13,2))) -> 32.167902 | K40: =1-B40/J40 -> 0.0034405887 | L40: =$H$13+($C$13-C40)/($C$13-$C$14)*($H$14-$H$13) -> 32.241591 | M40: =1-B40/L40 -> 0.005718244 | N40: ≈ Fixed-32 (suy biến)
A41: Cách đọc: Δ% < 0 nghĩa là Adaptive NHỎ hơn Fixed ở cùng L̄. Ba cột Fixed là ba cách nội suy giữa các điểm Fixed: 'chia sẻ thời gian' = trộn hai Fixed theo tỉ lệ token (đạt được thật bằng layout lai, nên đây là đối thủ hợp lệ nhưng yếu nhất); 'dây cung log₂' ; 'bậc 2' = ước lượng đường cong Fixed liên tục (Fixed với L không phải luỹ thừa 2 không chạy được trong cây này). Kết quả đáng tin nhất = cột bậc 2 (lợi ~0,5–1,0%); cột chia sẻ thời gian cho ~1,3–2,0%.
A43: D. DP-decode (mới) có tốt hơn DP-bits (cũ) ở cùng L̄ không?
A44: DP-bits λ=12000 (L̄≈86,05) | B44: =C23 -> 258127 | C44: =H23 -> 86.049849
A45: DP-decode λ=100 (L̄≈86,87) | B45: =C25 -> 257940 | C45: =H25 -> 86.865318
...

Sheet GD5_MauBang
A1: Giai đoạn 4–5 — Mẫu bảng Fixed vs Adaptive
A2: Điền ô xanh (input) hoặc vàng. Cột tính toán tự cập nhật. Chạy Fixed bằng CHÍNH adaptive_context_finezip.py (FixedPolicy) để so sánh cùng khuôn mã hoá.
A3: Original (B) | B3: =GD2_Baseline!B3 -> 1000000
A4: Hàng mẫu (xám) | B4: Số từ MockLM 6.037 token — KHÔNG phải kết quả thật; xoá khi có số thật.
A6: Policy | B6: Compressed (B) | C6: Ratio (gốc/nén) | D6: So với Fixed-512 (kích thước) | E6: Enc (s) | F6: Dec (s) | G6: Tiết kiệm enc so với Fixed-512 | H6: GPU peak (MiB) | I6: Lossless? | J6: Phân bố chunk 32/64/128/256/512 | K6: Ghi chú
A7: Fixed-32 | B7: 300576 | C7: =IF(ISNUMBER(B7),$B$3/B7,"") -> 3.3269456 | D7: =IF(AND(ISNUMBER(B7),ISNUMBER($B$11)),B7/$B$11-1,"") -> 0.40659176 | E7: 27.989156 | F7: CHƯA ĐO | G7: =IF(AND(ISNUMBER(E7),ISNUMBER($E$11)),1-E7/$E$11,"") -> -0.016553641 | I7: quick_check OK (mẫu) | J7: 8947 ×32
A8: Fixed-64 | B8: 271704 | C8: =IF(ISNUMBER(B8),$B$3/B8,"") -> 3.6804758 | D8: =IF(AND(ISNUMBER(B8),ISNUMBER($B$11)),B8/$B$11-1,"") -> 0.27148078 | E8: 28.5322 | F8: CHƯA ĐO | G8: =IF(AND(ISNUMBER(E8),ISNUMBER($E$11)),1-E8/$E$11,"") -> -0.036276756 | I8: quick_check OK (mẫu) | J8: 1/4473 (32/64)
A9: Fixed-128 | B9: 246976 | C9: =IF(ISNUMBER(B9),$B$3/B9,"") -> 4.0489764 | D9: =IF(AND(ISNUMBER(B9),ISNUMBER($B$11)),B9/$B$11-1,"") -> 0.15576229 | E9: 26.494509 | F9: CHƯA ĐO | G9: =IF(AND(ISNUMBER(E9),ISNUMBER($E$11)),1-E9/$E$11,"") -> 0.03773128 | I9: quick_check OK (mẫu) | J9: 1/1/2236 (32/64/128)
A10: Fixed-256 | B10: 228006 | C10: =IF(ISNUMBER(B10),$B$3/B10,"") -> 4.3858495 | D10: =IF(AND(ISNUMBER(B10),ISNUMBER($B$11)),B10/$B$11-1,"") -> 0.066989251 | E10: 27.012356 | F10: CHƯA ĐO | G10: =IF(AND(ISNUMBER(E10),ISNUMBER($E$11)),1-E10/$E$11,"") -> 0.018923305 | I10: quick_check OK (mẫu) | J10: 1/1/1118 (32/64/256)
A11: Fixed-512 | B11: 213691 | C11: =IF(ISNUMBER(B11),$B$3/B11,"") -> 4.6796543 | D11: =IF(AND(ISNUMBER(B11),ISNUMBER($B$11)),B11/$B$11-1,"") -> 0 | E11: 27.533378 | F11: CHƯA ĐO | G11: =IF(AND(ISNUMBER(E11),ISNUMBER($E$11)),1-E11/$E$11,"") -> 0 | I11: quick_check OK (mẫu) | J11: 1/1/559 (32/64/512)
A12: Adaptive-Feature (entropy+lặp) | C12: =IF(ISNUMBER(B12),$B$3/B12,"") | D12: =IF(AND(ISNUMBER(B12),ISNUMBER($B$11)),B12/$B$11-1,"") | G12: =IF(AND(ISNUMBER(E12),ISNUMBER($E$11)),1-E12/$E$11,"")
A13: Adaptive-DP λ=1000 | B13: 216534 | C13: =IF(ISNUMBER(B13),$B$3/B13,"") -> 4.6182124 | D13: =IF(AND(ISNUMBER(B13),ISNUMBER($B$11)),B13/$B$11-1,"") -> 0.013304257 | E13: 160.46178 | F13: 12000.909 | G13: =IF(AND(ISNUMBER(E13),ISNUMBER($E$11)),1-E13/$E$11,"") -> -4.8279003 | H13: 817.9292 | I13: True (decode đầy đủ) | J13: 1/17/50/397/346 | K13: v3, không escape. Dec lần trước (phiên khác) 9.523 s cùng blob. Enc = phân tích DP (~135 s) + lượt rank (~27 s).
A14: Adaptive-DP λ=2000 | C14: =IF(ISNUMBER(B14),$B$3/B14,"") | D14: =IF(AND(ISNUMBER(B14),ISNUMBER($B$11)),B14/$B$11-1,"") | G14: =IF(AND(ISNUMBER(E14),ISNUMBER($E$11)),1-E14/$E$11,"")
A15: Adaptive-DP λ=5000 | B15: 238128 | C15: =IF(ISNUMBER(B15),$B$3/B15,"") -> 4.1994222 | D15: =IF(AND(ISNUMBER(B15),ISNUMBER($B$11)),B15/$B$11-1,"") -> 0.11435671 | E15: 163.27003 | G15: =IF(AND(ISNUMBER(E15),ISNUMBER($E$11)),1-E15/$E$11,"") -> -4.9298944 | I15: quick_check OK (mẫu) | J15: 39/380/1401/292/13 | K15: v3. Chưa giải nén đầy đủ; bản v1 cùng layout đã giải nén đúng 4.605,5 s.
A16: Adaptive-DP λ=12000 | B16: 258127 | C16: =IF(ISNUMBER(B16),$B$3/B16,"") -> 3.874062 | D16: =IF(AND(ISNUMBER(B16),ISNUMBER($B$11)),B16/$B$11-1,"") -> 0.20794512 | E16: 163.87637 | G16: =IF(AND(ISNUMBER(E16),ISNUMBER($E$11)),1-E16/$E$11,"") -> -4.9519166 | I16: quick_check OK (mẫu) | J16: 563/2694/703/23/0 | K16: v3. Chưa giải nén đầy đủ.
A17: Adaptive-DP λ=40000 | B17: 288012 | C17: =IF(ISNUMBER(B17),$B$3/B17,"") -> 3.4720776 | D17: =IF(AND(ISNUMBER(B17),ISNUMBER($B$11)),B17/$B$11-1,"") -> 0.34779658 | E17: 164.63667 | G17: =IF(AND(ISNUMBER(E17),ISNUMBER($E$11)),1-E17/$E$11,"") -> -4.9795303 | I17: quick_check OK (mẫu) | J17: 6735/1100/3/0/0 | K17: v3. Chưa giải nén đầy đủ.
A19: VÍ DỤ (mock): Fixed-512 | B19: 4685 | C19: — | D19: =B19/$B$19-1 -> 0 | E19: 3.6538 | G19: =1-E19/$E$19 -> 0
A20: VÍ DỤ (mock): Adaptive-DP λ=3000 | B20: 4693 | C20: — | D20: =B20/$B$19-1 -> 0.0017075774 | E20: 2.3741 | G20: =1-E20/$E$19 -> 0.35023811
A22: Hàng mẫu chỉ minh hoạ cột D và G (chênh kích thước & tiết kiệm thời gian ước lượng); cột Ratio bỏ trống vì mock chỉ có 6.037 token.
A23: ⚠ Enc: Fixed ≈ 27 s (chỉ lượt rank). Adaptive ≈ 160–165 s (chấm điểm 5 mức L ≈ 135 s + lượt rank) → encoder chậm ~6×. Tất cả số Enc trong bảng này cùng một phiên Kaggle. So sánh ĐÚNG giữa Fixed và Adaptive phải ở cùng chi phí giải nén — xem GD5_SoSanh.
A24: Ablation (điền sau)
A25: Thí nghiệm | B25: Cấu hình | C25: Compressed (B) | D25: Enc (s) | E25: Kết luận ngắn
A26: A. Context | B26: Adaptive OFF: Fixed 32…512
A27: B. Online memorization | B27: No LoRA / LoRA (pipeline rank+bzip2)
A28: B. Online memorization | B28: Fixed-512 + LoRA vs Adaptive + LoRA
A29: C. Chính sách | B29: Feature (entropy) / Feature (lặp) / DP
A30: D. Dữ liệu | B30: Thuần văn xuôi / hỗn hợp wiki+code+bảng
